#VRML_SIM R2020a utf8
# Team 22 robot.

PROTO robot [
  field SFVec3f    translation  0 0 0
  field SFRotation rotation     0 1 0 0
  field SFFloat    bodyMass     1
]
{
  Robot {
    translation IS translation
    rotation IS rotation
    children [
        Transform {
        translation 0 0.0415 0
        children [
            Shape {
            appearance PBRAppearance {
                baseColor 0.333333 0.666667 0.498039
                roughness 1
                metalness 0
            }
            geometry DEF BODY Cylinder {
                height 0.08
                radius 0.045
            }
            }
        ]
        }
        HingeJoint {
        jointParameters HingeJointParameters {
            position 441.2483053744656
            axis -1 0 0
            anchor 0 0.025 0
        }
        device [
            RotationalMotor {
            name "left wheel motor"
            }
            PositionSensor {
            name "left wheel sensor"
            }
        ]
        endPoint Solid {
            translation -0.04500046262747595 0.025004496489366118 -4.2502863588089745e-06
            rotation 0.9999999999928134 1.5480734522948599e-06 3.4607451785945057e-06 -2.6997317108547505
            children [
            DEF WHEEL Transform {
                rotation 0 0 1 1.57
                children [
                Shape {
                    appearance PBRAppearance {
                    baseColor 1 0.666667 0.498039
                    roughness 1
                    metalness 0
                    }
                    geometry Cylinder {
                    height 0.01
                    radius 0.025
                    }
                }
                ]
            }
            ]
            name "right_wheel"
            boundingObject USE WHEEL
            physics DEF PHYSICS_WHEEL Physics {
            density -1
            mass 0.05
            }
        }
        }
        HingeJoint {
        jointParameters HingeJointParameters {
            position 193.83625701080442
            axis -1 0 0
            anchor 0 0.025 0
        }
        device [
            RotationalMotor {
            name "right wheel motor"
            }
            PositionSensor {
            name "right wheel sensor"
            }
        ]
        endPoint Solid {
            translation 0.045000530353957846 0.025006170262098254 3.3912351314335787e-06
            rotation 0.9999999990989931 -4.027233404452397e-05 1.3422113068739382e-05 0.16846389308431586
            children [
            USE WHEEL
            ]
            name "left_wheel"
            boundingObject USE WHEEL
            physics USE PHYSICS_WHEEL
        }
        }
        DistanceSensor {
            translation 0.05 0.06 0
            children [
                DEF SENSOR Shape {
                appearance PBRAppearance {
                    metalness 0
                }
                geometry Box {
                    size 0.01 0.01 0.01
                }
                }
            ]
            name "ds_left"
            boundingObject USE SENSOR
            physics Physics {
            }
        }
        DistanceSensor {
            translation -0.05 0.06 0
            rotation 0 1 0 3.141592653589793
            children [
                USE SENSOR
            ]
            name "ds_right"
            boundingObject USE SENSOR
            physics Physics {
            }
        }
        DistanceSensor {
            translation 0 0.05 -0.05
            rotation 0 1 0 1.5707996938995747
            children [
                USE SENSOR
            ]
            name "ds_front"
            boundingObject USE SENSOR
            physics Physics {
            }
        }
    ]
    boundingObject Transform {
        translation 0 0.0415 0
        children [
        USE BODY
        ]
    }
    physics Physics {
        density -1
        mass IS bodyMass
    }
    controller "Movement"
    linearVelocity 0.15342865227930866 -6.019982448896369e-07 0.033287947266661067
    angularVelocity 0.000553021731798631 -1.652198545216323e-06 7.288905287492074e-05
    }
}
